2020-11-24 16:55:16,919 ERROR: Exception on /login [GET] [in /home/isaac/miniconda3/envs/web_dev/lib/python3.8/site-packages/flask/app.py:1891]
Traceback (most recent call last):
  File "/home/isaac/miniconda3/envs/web_dev/lib/python3.8/site-packages/flask/app.py", line 2447, in wsgi_app
    response = self.full_dispatch_request()
  File "/home/isaac/miniconda3/envs/web_dev/lib/python3.8/site-packages/flask/app.py", line 1952, in full_dispatch_request
    rv = self.handle_user_exception(e)
  File "/home/isaac/miniconda3/envs/web_dev/lib/python3.8/site-packages/flask/app.py", line 1821, in handle_user_exception
    reraise(exc_type, exc_value, tb)
  File "/home/isaac/miniconda3/envs/web_dev/lib/python3.8/site-packages/flask/_compat.py", line 39, in reraise
    raise value
  File "/home/isaac/miniconda3/envs/web_dev/lib/python3.8/site-packages/flask/app.py", line 1950, in full_dispatch_request
    rv = self.dispatch_request()
  File "/home/isaac/miniconda3/envs/web_dev/lib/python3.8/site-packages/flask/app.py", line 1936, in dispatch_request
    return self.view_functions[rule.endpoint](**req.view_args)
  File "/home/isaac/Documents/examples/flask/app/routes.py", line 48, in login
    return render_template('login.html', title='Sign In', form=form)
  File "/home/isaac/miniconda3/envs/web_dev/lib/python3.8/site-packages/flask/templating.py", line 137, in render_template
    return _render(
  File "/home/isaac/miniconda3/envs/web_dev/lib/python3.8/site-packages/flask/templating.py", line 120, in _render
    rv = template.render(context)
  File "/home/isaac/miniconda3/envs/web_dev/lib/python3.8/site-packages/jinja2/environment.py", line 1090, in render
    self.environment.handle_exception()
  File "/home/isaac/miniconda3/envs/web_dev/lib/python3.8/site-packages/jinja2/environment.py", line 832, in handle_exception
    reraise(*rewrite_traceback_stack(source=source))
  File "/home/isaac/miniconda3/envs/web_dev/lib/python3.8/site-packages/jinja2/_compat.py", line 28, in reraise
    raise value.with_traceback(tb)
  File "/home/isaac/Documents/examples/flask/app/templates/login.html", line 1, in top-level template code
    {% extends "base.html" %}
  File "/home/isaac/Documents/examples/flask/app/templates/base.html", line 31, in top-level template code
    {% block content %}{% endblock %}
  File "/home/isaac/Documents/examples/flask/app/templates/login.html", line 26, in block "content"
    <a href="{{ url_for('reset_password_request') }}">Click to Reset It</a>
  File "/home/isaac/miniconda3/envs/web_dev/lib/python3.8/site-packages/flask/helpers.py", line 370, in url_for
    return appctx.app.handle_url_build_error(error, endpoint, values)
  File "/home/isaac/miniconda3/envs/web_dev/lib/python3.8/site-packages/flask/app.py", line 2216, in handle_url_build_error
    reraise(exc_type, exc_value, tb)
  File "/home/isaac/miniconda3/envs/web_dev/lib/python3.8/site-packages/flask/_compat.py", line 39, in reraise
    raise value
  File "/home/isaac/miniconda3/envs/web_dev/lib/python3.8/site-packages/flask/helpers.py", line 357, in url_for
    rv = url_adapter.build(
  File "/home/isaac/miniconda3/envs/web_dev/lib/python3.8/site-packages/werkzeug/routing.py", line 2179, in build
    raise BuildError(endpoint, values, method, self)
werkzeug.routing.BuildError: Could not build url for endpoint 'reset_password_request'. Did you mean 'edit_profile' instead?
